[2024-04-16T15:45:15.180+0000] {local_task_job_runner.py:120} INFO - ::group::Pre task execution logs
[2024-04-16T15:45:15.307+0000] {taskinstance.py:2073} INFO - Dependencies all met for dep_context=non-requeueable deps ti=<TaskInstance: Superstore_dataprep_kuzmenko.data_prep_superstore manual__2024-04-16T15:45:04.549980+00:00 [queued]>
[2024-04-16T15:45:15.340+0000] {taskinstance.py:2073} INFO - Dependencies all met for dep_context=requeueable deps ti=<TaskInstance: Superstore_dataprep_kuzmenko.data_prep_superstore manual__2024-04-16T15:45:04.549980+00:00 [queued]>
[2024-04-16T15:45:15.342+0000] {taskinstance.py:2303} INFO - Starting attempt 1 of 1
[2024-04-16T15:45:15.379+0000] {taskinstance.py:2327} INFO - Executing <Task(PythonOperator): data_prep_superstore> on 2024-04-16 15:45:04.549980+00:00
[2024-04-16T15:45:15.393+0000] {warnings.py:110} WARNING - /home/***/.local/lib/python3.12/site-packages/***/task/task_runner/standard_task_runner.py:61: DeprecationWarning: This process (pid=979) is multi-threaded, use of fork() may lead to deadlocks in the child.
  pid = os.fork()

[2024-04-16T15:45:15.396+0000] {standard_task_runner.py:63} INFO - Started process 980 to run task
[2024-04-16T15:45:15.395+0000] {standard_task_runner.py:90} INFO - Running: ['***', 'tasks', 'run', 'Superstore_dataprep_kuzmenko', 'data_prep_superstore', 'manual__2024-04-16T15:45:04.549980+00:00', '--job-id', '12', '--raw', '--subdir', 'DAGS_FOLDER/superstore_dag_by_Kuzmenko.py', '--cfg-path', '/tmp/tmp9t5_5xql']
[2024-04-16T15:45:15.397+0000] {standard_task_runner.py:91} INFO - Job 12: Subtask data_prep_superstore
[2024-04-16T15:45:15.466+0000] {task_command.py:426} INFO - Running <TaskInstance: Superstore_dataprep_kuzmenko.data_prep_superstore manual__2024-04-16T15:45:04.549980+00:00 [running]> on host b3ab91a725a8
[2024-04-16T15:45:15.628+0000] {taskinstance.py:2644} INFO - Exporting env vars: AIRFLOW_CTX_DAG_OWNER='KuzmenkoSV' AIRFLOW_CTX_DAG_ID='Superstore_dataprep_kuzmenko' AIRFLOW_CTX_TASK_ID='data_prep_superstore' AIRFLOW_CTX_EXECUTION_DATE='2024-04-16T15:45:04.549980+00:00' AIRFLOW_CTX_TRY_NUMBER='1' AIRFLOW_CTX_DAG_RUN_ID='manual__2024-04-16T15:45:04.549980+00:00'
[2024-04-16T15:45:15.630+0000] {taskinstance.py:430} INFO - ::endgroup::
[2024-04-16T15:45:15.744+0000] {taskinstance.py:441} INFO - ::group::Post task execution logs
[2024-04-16T15:45:15.746+0000] {taskinstance.py:2890} ERROR - Task failed with exception
Traceback (most recent call last):
  File "/home/airflow/.local/lib/python3.12/site-packages/airflow/models/taskinstance.py", line 465, in _execute_task
    result = _execute_callable(context=context, **execute_callable_kwargs)
             ^^^^^^^^^^^^^^^^^^^^^^^^^^^^^^^^^^^^^^^^^^^^^^^^^^^^^^^^^^^^^
  File "/home/airflow/.local/lib/python3.12/site-packages/airflow/models/taskinstance.py", line 432, in _execute_callable
    return execute_callable(context=context, **execute_callable_kwargs)
           ^^^^^^^^^^^^^^^^^^^^^^^^^^^^^^^^^^^^^^^^^^^^^^^^^^^^^^^^^^^^
  File "/home/airflow/.local/lib/python3.12/site-packages/airflow/models/baseoperator.py", line 400, in wrapper
    return func(self, *args, **kwargs)
           ^^^^^^^^^^^^^^^^^^^^^^^^^^^
  File "/home/airflow/.local/lib/python3.12/site-packages/airflow/operators/python.py", line 235, in execute
    return_value = self.execute_callable()
                   ^^^^^^^^^^^^^^^^^^^^^^^
  File "/home/airflow/.local/lib/python3.12/site-packages/airflow/operators/python.py", line 252, in execute_callable
    return self.python_callable(*self.op_args, **self.op_kwargs)
           ^^^^^^^^^^^^^^^^^^^^^^^^^^^^^^^^^^^^^^^^^^^^^^^^^^^^^
  File "/opt/airflow/dags/superstore_dag_by_Kuzmenko.py", line 14, in data_prep
    import pandasfff as pd
ModuleNotFoundError: No module named 'pandasfff'
[2024-04-16T15:45:15.793+0000] {taskinstance.py:1205} INFO - Marking task as FAILED. dag_id=Superstore_dataprep_kuzmenko, task_id=data_prep_superstore, execution_date=20240416T154504, start_date=20240416T154515, end_date=20240416T154515
[2024-04-16T15:45:15.831+0000] {standard_task_runner.py:110} ERROR - Failed to execute job 12 for task data_prep_superstore (No module named 'pandasfff'; 980)
[2024-04-16T15:45:15.871+0000] {local_task_job_runner.py:240} INFO - Task exited with return code 1
[2024-04-16T15:45:15.918+0000] {taskinstance.py:3482} INFO - 0 downstream tasks scheduled from follow-on schedule check
[2024-04-16T15:45:15.929+0000] {local_task_job_runner.py:222} INFO - ::endgroup::
